[2023-12-22T02:35:40.956+0000] {taskinstance.py:1159} INFO - Dependencies all met for dep_context=non-requeueable deps ti=<TaskInstance: liverpool_dag.connect_to_db manual__2023-12-22T02:33:34.223013+00:00 [queued]>
[2023-12-22T02:35:40.972+0000] {taskinstance.py:1159} INFO - Dependencies all met for dep_context=requeueable deps ti=<TaskInstance: liverpool_dag.connect_to_db manual__2023-12-22T02:33:34.223013+00:00 [queued]>
[2023-12-22T02:35:40.973+0000] {taskinstance.py:1361} INFO - Starting attempt 3 of 4
[2023-12-22T02:35:40.996+0000] {taskinstance.py:1382} INFO - Executing <Task(PythonOperator): connect_to_db> on 2023-12-22 02:33:34.223013+00:00
[2023-12-22T02:35:41.004+0000] {standard_task_runner.py:57} INFO - Started process 269 to run task
[2023-12-22T02:35:41.010+0000] {standard_task_runner.py:84} INFO - Running: ['***', 'tasks', 'run', 'liverpool_dag', 'connect_to_db', 'manual__2023-12-22T02:33:34.223013+00:00', '--job-id', '437', '--raw', '--subdir', 'DAGS_FOLDER/liverpool.py', '--cfg-path', '/tmp/tmpjc2ae7eo']
[2023-12-22T02:35:41.016+0000] {standard_task_runner.py:85} INFO - Job 437: Subtask connect_to_db
[2023-12-22T02:35:41.121+0000] {task_command.py:416} INFO - Running <TaskInstance: liverpool_dag.connect_to_db manual__2023-12-22T02:33:34.223013+00:00 [running]> on host d017a9b7b4e6
[2023-12-22T02:35:41.299+0000] {taskinstance.py:1662} INFO - Exporting env vars: AIRFLOW_CTX_DAG_OWNER='***' AIRFLOW_CTX_DAG_ID='liverpool_dag' AIRFLOW_CTX_TASK_ID='connect_to_db' AIRFLOW_CTX_EXECUTION_DATE='2023-12-22T02:33:34.223013+00:00' AIRFLOW_CTX_TRY_NUMBER='3' AIRFLOW_CTX_DAG_RUN_ID='manual__2023-12-22T02:33:34.223013+00:00'
[2023-12-22T02:35:41.301+0000] {taskinstance.py:1937} ERROR - Task failed with exception
Traceback (most recent call last):
  File "/home/airflow/.local/lib/python3.8/site-packages/airflow/operators/python.py", line 192, in execute
    return_value = self.execute_callable()
  File "/home/airflow/.local/lib/python3.8/site-packages/airflow/operators/python.py", line 209, in execute_callable
    return self.python_callable(*self.op_args, **self.op_kwargs)
TypeError: build_conn_from_***_conn_id() missing 1 required positional argument: 'config_file_path'
[2023-12-22T02:35:41.324+0000] {taskinstance.py:1400} INFO - Marking task as UP_FOR_RETRY. dag_id=liverpool_dag, task_id=connect_to_db, execution_date=20231222T023334, start_date=20231222T023540, end_date=20231222T023541
[2023-12-22T02:35:41.344+0000] {standard_task_runner.py:104} ERROR - Failed to execute job 437 for task connect_to_db (build_conn_from_***_conn_id() missing 1 required positional argument: 'config_file_path'; 269)
[2023-12-22T02:35:41.383+0000] {local_task_job_runner.py:228} INFO - Task exited with return code 1
[2023-12-22T02:35:41.461+0000] {taskinstance.py:2778} INFO - 0 downstream tasks scheduled from follow-on schedule check
