[2023-12-18T19:33:10.854+0000] {taskinstance.py:1159} INFO - Dependencies all met for dep_context=non-requeueable deps ti=<TaskInstance: liverpool_dag.process_data manual__2023-12-18T19:30:46.484881+00:00 [queued]>
[2023-12-18T19:33:10.870+0000] {taskinstance.py:1159} INFO - Dependencies all met for dep_context=requeueable deps ti=<TaskInstance: liverpool_dag.process_data manual__2023-12-18T19:30:46.484881+00:00 [queued]>
[2023-12-18T19:33:10.871+0000] {taskinstance.py:1361} INFO - Starting attempt 3 of 4
[2023-12-18T19:33:10.890+0000] {taskinstance.py:1382} INFO - Executing <Task(PythonOperator): process_data> on 2023-12-18 19:30:46.484881+00:00
[2023-12-18T19:33:10.901+0000] {standard_task_runner.py:57} INFO - Started process 280 to run task
[2023-12-18T19:33:10.905+0000] {standard_task_runner.py:84} INFO - Running: ['***', 'tasks', 'run', 'liverpool_dag', 'process_data', 'manual__2023-12-18T19:30:46.484881+00:00', '--job-id', '141', '--raw', '--subdir', 'DAGS_FOLDER/liverpool.py', '--cfg-path', '/tmp/tmp1dqt8pyz']
[2023-12-18T19:33:10.910+0000] {standard_task_runner.py:85} INFO - Job 141: Subtask process_data
[2023-12-18T19:33:10.984+0000] {task_command.py:416} INFO - Running <TaskInstance: liverpool_dag.process_data manual__2023-12-18T19:30:46.484881+00:00 [running]> on host d017a9b7b4e6
[2023-12-18T19:33:11.102+0000] {taskinstance.py:1662} INFO - Exporting env vars: AIRFLOW_CTX_DAG_OWNER='***' AIRFLOW_CTX_DAG_ID='liverpool_dag' AIRFLOW_CTX_TASK_ID='process_data' AIRFLOW_CTX_EXECUTION_DATE='2023-12-18T19:30:46.484881+00:00' AIRFLOW_CTX_TRY_NUMBER='3' AIRFLOW_CTX_DAG_RUN_ID='manual__2023-12-18T19:30:46.484881+00:00'
[2023-12-18T19:33:11.108+0000] {taskinstance.py:1937} ERROR - Task failed with exception
Traceback (most recent call last):
  File "/home/airflow/.local/lib/python3.8/site-packages/airflow/operators/python.py", line 192, in execute
    return_value = self.execute_callable()
  File "/home/airflow/.local/lib/python3.8/site-packages/airflow/operators/python.py", line 209, in execute_callable
    return self.python_callable(*self.op_args, **self.op_kwargs)
TypeError: procesar_datos() missing 1 required positional argument: 'data'
[2023-12-18T19:33:11.126+0000] {taskinstance.py:1400} INFO - Marking task as UP_FOR_RETRY. dag_id=liverpool_dag, task_id=process_data, execution_date=20231218T193046, start_date=20231218T193310, end_date=20231218T193311
[2023-12-18T19:33:11.141+0000] {standard_task_runner.py:104} ERROR - Failed to execute job 141 for task process_data (procesar_datos() missing 1 required positional argument: 'data'; 280)
[2023-12-18T19:33:11.159+0000] {local_task_job_runner.py:228} INFO - Task exited with return code 1
[2023-12-18T19:33:11.190+0000] {taskinstance.py:2778} INFO - 0 downstream tasks scheduled from follow-on schedule check
