[2023-12-18T19:12:02.514+0000] {taskinstance.py:1159} INFO - Dependencies all met for dep_context=non-requeueable deps ti=<TaskInstance: liverpool_dag.process_data manual__2023-12-18T19:09:26.072347+00:00 [queued]>
[2023-12-18T19:12:02.563+0000] {taskinstance.py:1159} INFO - Dependencies all met for dep_context=requeueable deps ti=<TaskInstance: liverpool_dag.process_data manual__2023-12-18T19:09:26.072347+00:00 [queued]>
[2023-12-18T19:12:02.564+0000] {taskinstance.py:1361} INFO - Starting attempt 2 of 4
[2023-12-18T19:12:02.641+0000] {taskinstance.py:1382} INFO - Executing <Task(PythonOperator): process_data> on 2023-12-18 19:09:26.072347+00:00
[2023-12-18T19:12:02.816+0000] {standard_task_runner.py:57} INFO - Started process 246 to run task
[2023-12-18T19:12:02.865+0000] {standard_task_runner.py:84} INFO - Running: ['***', 'tasks', 'run', 'liverpool_dag', 'process_data', 'manual__2023-12-18T19:09:26.072347+00:00', '--job-id', '132', '--raw', '--subdir', 'DAGS_FOLDER/liverpool.py', '--cfg-path', '/tmp/tmpdbo9hcqz']
[2023-12-18T19:12:02.882+0000] {standard_task_runner.py:85} INFO - Job 132: Subtask process_data
[2023-12-18T19:12:03.160+0000] {task_command.py:416} INFO - Running <TaskInstance: liverpool_dag.process_data manual__2023-12-18T19:09:26.072347+00:00 [running]> on host d017a9b7b4e6
[2023-12-18T19:12:03.585+0000] {taskinstance.py:1662} INFO - Exporting env vars: AIRFLOW_CTX_DAG_OWNER='***' AIRFLOW_CTX_DAG_ID='liverpool_dag' AIRFLOW_CTX_TASK_ID='process_data' AIRFLOW_CTX_EXECUTION_DATE='2023-12-18T19:09:26.072347+00:00' AIRFLOW_CTX_TRY_NUMBER='2' AIRFLOW_CTX_DAG_RUN_ID='manual__2023-12-18T19:09:26.072347+00:00'
[2023-12-18T19:12:03.596+0000] {taskinstance.py:1937} ERROR - Task failed with exception
Traceback (most recent call last):
  File "/home/airflow/.local/lib/python3.8/site-packages/airflow/operators/python.py", line 192, in execute
    return_value = self.execute_callable()
  File "/home/airflow/.local/lib/python3.8/site-packages/airflow/operators/python.py", line 209, in execute_callable
    return self.python_callable(*self.op_args, **self.op_kwargs)
TypeError: procesar_datos() missing 1 required positional argument: 'data'
[2023-12-18T19:12:03.695+0000] {taskinstance.py:1400} INFO - Marking task as UP_FOR_RETRY. dag_id=liverpool_dag, task_id=process_data, execution_date=20231218T190926, start_date=20231218T191202, end_date=20231218T191203
[2023-12-18T19:12:03.863+0000] {standard_task_runner.py:104} ERROR - Failed to execute job 132 for task process_data (procesar_datos() missing 1 required positional argument: 'data'; 246)
[2023-12-18T19:12:03.919+0000] {local_task_job_runner.py:228} INFO - Task exited with return code 1
[2023-12-18T19:12:04.024+0000] {taskinstance.py:2778} INFO - 0 downstream tasks scheduled from follow-on schedule check
