[2023-12-18T19:53:11.710+0000] {taskinstance.py:1159} INFO - Dependencies all met for dep_context=non-requeueable deps ti=<TaskInstance: liverpool_dag.load_data_to_db manual__2023-12-18T19:52:59.094608+00:00 [queued]>
[2023-12-18T19:53:11.729+0000] {taskinstance.py:1159} INFO - Dependencies all met for dep_context=requeueable deps ti=<TaskInstance: liverpool_dag.load_data_to_db manual__2023-12-18T19:52:59.094608+00:00 [queued]>
[2023-12-18T19:53:11.730+0000] {taskinstance.py:1361} INFO - Starting attempt 1 of 4
[2023-12-18T19:53:11.756+0000] {taskinstance.py:1382} INFO - Executing <Task(PythonOperator): load_data_to_db> on 2023-12-18 19:52:59.094608+00:00
[2023-12-18T19:53:11.771+0000] {standard_task_runner.py:57} INFO - Started process 211 to run task
[2023-12-18T19:53:11.778+0000] {standard_task_runner.py:84} INFO - Running: ['***', 'tasks', 'run', 'liverpool_dag', 'load_data_to_db', 'manual__2023-12-18T19:52:59.094608+00:00', '--job-id', '156', '--raw', '--subdir', 'DAGS_FOLDER/liverpool.py', '--cfg-path', '/tmp/tmpe3yt0pqq']
[2023-12-18T19:53:11.785+0000] {standard_task_runner.py:85} INFO - Job 156: Subtask load_data_to_db
[2023-12-18T19:53:11.937+0000] {task_command.py:416} INFO - Running <TaskInstance: liverpool_dag.load_data_to_db manual__2023-12-18T19:52:59.094608+00:00 [running]> on host d017a9b7b4e6
[2023-12-18T19:53:12.169+0000] {taskinstance.py:1662} INFO - Exporting env vars: AIRFLOW_CTX_DAG_OWNER='***' AIRFLOW_CTX_DAG_ID='liverpool_dag' AIRFLOW_CTX_TASK_ID='load_data_to_db' AIRFLOW_CTX_EXECUTION_DATE='2023-12-18T19:52:59.094608+00:00' AIRFLOW_CTX_TRY_NUMBER='1' AIRFLOW_CTX_DAG_RUN_ID='manual__2023-12-18T19:52:59.094608+00:00'
[2023-12-18T19:53:12.173+0000] {taskinstance.py:1937} ERROR - Task failed with exception
Traceback (most recent call last):
  File "/home/airflow/.local/lib/python3.8/site-packages/airflow/operators/python.py", line 192, in execute
    return_value = self.execute_callable()
  File "/home/airflow/.local/lib/python3.8/site-packages/airflow/operators/python.py", line 209, in execute_callable
    return self.python_callable(*self.op_args, **self.op_kwargs)
TypeError: cargar_datos_a_bd() missing 1 required positional argument: 'df'
[2023-12-18T19:53:12.202+0000] {taskinstance.py:1400} INFO - Marking task as UP_FOR_RETRY. dag_id=liverpool_dag, task_id=load_data_to_db, execution_date=20231218T195259, start_date=20231218T195311, end_date=20231218T195312
[2023-12-18T19:53:12.225+0000] {standard_task_runner.py:104} ERROR - Failed to execute job 156 for task load_data_to_db (cargar_datos_a_bd() missing 1 required positional argument: 'df'; 211)
[2023-12-18T19:53:12.271+0000] {local_task_job_runner.py:228} INFO - Task exited with return code 1
[2023-12-18T19:53:12.319+0000] {taskinstance.py:2778} INFO - 0 downstream tasks scheduled from follow-on schedule check
