[2023-12-21T15:56:28.880+0000] {taskinstance.py:1159} INFO - Dependencies all met for dep_context=non-requeueable deps ti=<TaskInstance: liverpool_dag.load_data manual__2023-12-21T15:54:13.313715+00:00 [queued]>
[2023-12-21T15:56:28.893+0000] {taskinstance.py:1159} INFO - Dependencies all met for dep_context=requeueable deps ti=<TaskInstance: liverpool_dag.load_data manual__2023-12-21T15:54:13.313715+00:00 [queued]>
[2023-12-21T15:56:28.894+0000] {taskinstance.py:1361} INFO - Starting attempt 3 of 4
[2023-12-21T15:56:28.913+0000] {taskinstance.py:1382} INFO - Executing <Task(PythonOperator): load_data> on 2023-12-21 15:54:13.313715+00:00
[2023-12-21T15:56:28.918+0000] {standard_task_runner.py:57} INFO - Started process 301 to run task
[2023-12-21T15:56:28.921+0000] {standard_task_runner.py:84} INFO - Running: ['***', 'tasks', 'run', 'liverpool_dag', 'load_data', 'manual__2023-12-21T15:54:13.313715+00:00', '--job-id', '308', '--raw', '--subdir', 'DAGS_FOLDER/liverpool.py', '--cfg-path', '/tmp/tmpxsgjpfgx']
[2023-12-21T15:56:28.925+0000] {standard_task_runner.py:85} INFO - Job 308: Subtask load_data
[2023-12-21T15:56:28.985+0000] {task_command.py:416} INFO - Running <TaskInstance: liverpool_dag.load_data manual__2023-12-21T15:54:13.313715+00:00 [running]> on host d017a9b7b4e6
[2023-12-21T15:56:29.178+0000] {taskinstance.py:1662} INFO - Exporting env vars: AIRFLOW_CTX_DAG_OWNER='***' AIRFLOW_CTX_DAG_ID='liverpool_dag' AIRFLOW_CTX_TASK_ID='load_data' AIRFLOW_CTX_EXECUTION_DATE='2023-12-21T15:54:13.313715+00:00' AIRFLOW_CTX_TRY_NUMBER='3' AIRFLOW_CTX_DAG_RUN_ID='manual__2023-12-21T15:54:13.313715+00:00'
[2023-12-21T15:56:29.212+0000] {utils.py:23} ERROR - Error al conectarse a la base de datos: Can't load plugin: sqlalchemy.dialects:***
[2023-12-21T15:56:29.213+0000] {liverpool.py:39} ERROR - No se pudo obtener el motor de la base de datos.
[2023-12-21T15:56:29.214+0000] {taskinstance.py:1937} ERROR - Task failed with exception
Traceback (most recent call last):
  File "/home/airflow/.local/lib/python3.8/site-packages/airflow/operators/python.py", line 192, in execute
    return_value = self.execute_callable()
  File "/home/airflow/.local/lib/python3.8/site-packages/airflow/operators/python.py", line 209, in execute_callable
    return self.python_callable(*self.op_args, **self.op_kwargs)
  File "/opt/airflow/dags/liverpool.py", line 40, in load_data_callable
    raise RuntimeError(error_msg)
RuntimeError: No se pudo obtener el motor de la base de datos.
[2023-12-21T15:56:29.229+0000] {taskinstance.py:1400} INFO - Marking task as UP_FOR_RETRY. dag_id=liverpool_dag, task_id=load_data, execution_date=20231221T155413, start_date=20231221T155628, end_date=20231221T155629
[2023-12-21T15:56:29.243+0000] {standard_task_runner.py:104} ERROR - Failed to execute job 308 for task load_data (No se pudo obtener el motor de la base de datos.; 301)
[2023-12-21T15:56:29.254+0000] {local_task_job_runner.py:228} INFO - Task exited with return code 1
[2023-12-21T15:56:29.274+0000] {taskinstance.py:2778} INFO - 0 downstream tasks scheduled from follow-on schedule check
