[2023-12-22T03:23:30.479+0000] {taskinstance.py:1159} INFO - Dependencies all met for dep_context=non-requeueable deps ti=<TaskInstance: liverpool_dag.connect_to_db manual__2023-12-22T03:23:28.042580+00:00 [queued]>
[2023-12-22T03:23:30.498+0000] {taskinstance.py:1159} INFO - Dependencies all met for dep_context=requeueable deps ti=<TaskInstance: liverpool_dag.connect_to_db manual__2023-12-22T03:23:28.042580+00:00 [queued]>
[2023-12-22T03:23:30.499+0000] {taskinstance.py:1361} INFO - Starting attempt 1 of 4
[2023-12-22T03:23:30.521+0000] {taskinstance.py:1382} INFO - Executing <Task(PythonOperator): connect_to_db> on 2023-12-22 03:23:28.042580+00:00
[2023-12-22T03:23:30.531+0000] {standard_task_runner.py:57} INFO - Started process 209 to run task
[2023-12-22T03:23:30.542+0000] {standard_task_runner.py:84} INFO - Running: ['***', 'tasks', 'run', 'liverpool_dag', 'connect_to_db', 'manual__2023-12-22T03:23:28.042580+00:00', '--job-id', '472', '--raw', '--subdir', 'DAGS_FOLDER/liverpool.py', '--cfg-path', '/tmp/tmpygiez3yb']
[2023-12-22T03:23:30.548+0000] {standard_task_runner.py:85} INFO - Job 472: Subtask connect_to_db
[2023-12-22T03:23:30.676+0000] {task_command.py:416} INFO - Running <TaskInstance: liverpool_dag.connect_to_db manual__2023-12-22T03:23:28.042580+00:00 [running]> on host d017a9b7b4e6
[2023-12-22T03:23:30.881+0000] {taskinstance.py:1662} INFO - Exporting env vars: AIRFLOW_CTX_DAG_OWNER='***' AIRFLOW_CTX_DAG_ID='liverpool_dag' AIRFLOW_CTX_TASK_ID='connect_to_db' AIRFLOW_CTX_EXECUTION_DATE='2023-12-22T03:23:28.042580+00:00' AIRFLOW_CTX_TRY_NUMBER='1' AIRFLOW_CTX_DAG_RUN_ID='manual__2023-12-22T03:23:28.042580+00:00'
[2023-12-22T03:23:30.885+0000] {utils.py:50} ERROR - Sección 'redshift' no encontrada en el archivo de configuración.
[2023-12-22T03:23:30.886+0000] {taskinstance.py:1937} ERROR - Task failed with exception
Traceback (most recent call last):
  File "/home/airflow/.local/lib/python3.8/site-packages/airflow/operators/python.py", line 192, in execute
    return_value = self.execute_callable()
  File "/home/airflow/.local/lib/python3.8/site-packages/airflow/operators/python.py", line 209, in execute_callable
    return self.python_callable(*self.op_args, **self.op_kwargs)
  File "/opt/airflow/scripts/utils.py", line 51, in build_conn_from_airflow_conn_id
    raise KeyError(error_msg)  # Levanta una excepción KeyError para indicar la falta de la sección 'redshift'
KeyError: "Sección 'redshift' no encontrada en el archivo de configuración."
[2023-12-22T03:23:30.928+0000] {taskinstance.py:1400} INFO - Marking task as UP_FOR_RETRY. dag_id=liverpool_dag, task_id=connect_to_db, execution_date=20231222T032328, start_date=20231222T032330, end_date=20231222T032330
[2023-12-22T03:23:30.956+0000] {standard_task_runner.py:104} ERROR - Failed to execute job 472 for task connect_to_db ("Sección 'redshift' no encontrada en el archivo de configuración."; 209)
[2023-12-22T03:23:31.002+0000] {local_task_job_runner.py:228} INFO - Task exited with return code 1
[2023-12-22T03:23:31.072+0000] {taskinstance.py:2778} INFO - 0 downstream tasks scheduled from follow-on schedule check
