[2023-12-22T03:24:32.130+0000] {taskinstance.py:1159} INFO - Dependencies all met for dep_context=non-requeueable deps ti=<TaskInstance: liverpool_dag.connect_to_db manual__2023-12-22T03:23:28.042580+00:00 [queued]>
[2023-12-22T03:24:32.144+0000] {taskinstance.py:1159} INFO - Dependencies all met for dep_context=requeueable deps ti=<TaskInstance: liverpool_dag.connect_to_db manual__2023-12-22T03:23:28.042580+00:00 [queued]>
[2023-12-22T03:24:32.145+0000] {taskinstance.py:1361} INFO - Starting attempt 2 of 4
[2023-12-22T03:24:32.167+0000] {taskinstance.py:1382} INFO - Executing <Task(PythonOperator): connect_to_db> on 2023-12-22 03:23:28.042580+00:00
[2023-12-22T03:24:32.177+0000] {standard_task_runner.py:57} INFO - Started process 248 to run task
[2023-12-22T03:24:32.182+0000] {standard_task_runner.py:84} INFO - Running: ['***', 'tasks', 'run', 'liverpool_dag', 'connect_to_db', 'manual__2023-12-22T03:23:28.042580+00:00', '--job-id', '473', '--raw', '--subdir', 'DAGS_FOLDER/liverpool.py', '--cfg-path', '/tmp/tmpc4l0z3td']
[2023-12-22T03:24:32.187+0000] {standard_task_runner.py:85} INFO - Job 473: Subtask connect_to_db
[2023-12-22T03:24:32.289+0000] {task_command.py:416} INFO - Running <TaskInstance: liverpool_dag.connect_to_db manual__2023-12-22T03:23:28.042580+00:00 [running]> on host d017a9b7b4e6
[2023-12-22T03:24:32.436+0000] {taskinstance.py:1662} INFO - Exporting env vars: AIRFLOW_CTX_DAG_OWNER='***' AIRFLOW_CTX_DAG_ID='liverpool_dag' AIRFLOW_CTX_TASK_ID='connect_to_db' AIRFLOW_CTX_EXECUTION_DATE='2023-12-22T03:23:28.042580+00:00' AIRFLOW_CTX_TRY_NUMBER='2' AIRFLOW_CTX_DAG_RUN_ID='manual__2023-12-22T03:23:28.042580+00:00'
[2023-12-22T03:24:32.439+0000] {utils.py:50} ERROR - Sección 'redshift' no encontrada en el archivo de configuración.
[2023-12-22T03:24:32.440+0000] {taskinstance.py:1937} ERROR - Task failed with exception
Traceback (most recent call last):
  File "/home/airflow/.local/lib/python3.8/site-packages/airflow/operators/python.py", line 192, in execute
    return_value = self.execute_callable()
  File "/home/airflow/.local/lib/python3.8/site-packages/airflow/operators/python.py", line 209, in execute_callable
    return self.python_callable(*self.op_args, **self.op_kwargs)
  File "/opt/airflow/scripts/utils.py", line 51, in build_conn_from_airflow_conn_id
    raise KeyError(error_msg)  # Levanta una excepción KeyError para indicar la falta de la sección 'redshift'
KeyError: "Sección 'redshift' no encontrada en el archivo de configuración."
[2023-12-22T03:24:32.464+0000] {taskinstance.py:1400} INFO - Marking task as UP_FOR_RETRY. dag_id=liverpool_dag, task_id=connect_to_db, execution_date=20231222T032328, start_date=20231222T032432, end_date=20231222T032432
[2023-12-22T03:24:32.481+0000] {standard_task_runner.py:104} ERROR - Failed to execute job 473 for task connect_to_db ("Sección 'redshift' no encontrada en el archivo de configuración."; 248)
[2023-12-22T03:24:32.516+0000] {local_task_job_runner.py:228} INFO - Task exited with return code 1
[2023-12-22T03:24:32.586+0000] {taskinstance.py:2778} INFO - 0 downstream tasks scheduled from follow-on schedule check
