[2023-12-21T23:42:24.324+0000] {taskinstance.py:1159} INFO - Dependencies all met for dep_context=non-requeueable deps ti=<TaskInstance: liverpool_dag.send_email_on_failure manual__2023-12-21T23:37:08.623264+00:00 [queued]>
[2023-12-21T23:42:24.347+0000] {taskinstance.py:1159} INFO - Dependencies all met for dep_context=requeueable deps ti=<TaskInstance: liverpool_dag.send_email_on_failure manual__2023-12-21T23:37:08.623264+00:00 [queued]>
[2023-12-21T23:42:24.349+0000] {taskinstance.py:1361} INFO - Starting attempt 3 of 4
[2023-12-21T23:42:24.400+0000] {taskinstance.py:1382} INFO - Executing <Task(PythonOperator): send_email_on_failure> on 2023-12-21 23:37:08.623264+00:00
[2023-12-21T23:42:24.410+0000] {standard_task_runner.py:57} INFO - Started process 407 to run task
[2023-12-21T23:42:24.418+0000] {standard_task_runner.py:84} INFO - Running: ['***', 'tasks', 'run', 'liverpool_dag', 'send_email_on_failure', 'manual__2023-12-21T23:37:08.623264+00:00', '--job-id', '389', '--raw', '--subdir', 'DAGS_FOLDER/liverpool.py', '--cfg-path', '/tmp/tmp_9zizca4']
[2023-12-21T23:42:24.427+0000] {standard_task_runner.py:85} INFO - Job 389: Subtask send_email_on_failure
[2023-12-21T23:42:24.540+0000] {task_command.py:416} INFO - Running <TaskInstance: liverpool_dag.send_email_on_failure manual__2023-12-21T23:37:08.623264+00:00 [running]> on host d017a9b7b4e6
[2023-12-21T23:42:24.679+0000] {taskinstance.py:1662} INFO - Exporting env vars: AIRFLOW_CTX_DAG_OWNER='***' AIRFLOW_CTX_DAG_ID='liverpool_dag' AIRFLOW_CTX_TASK_ID='send_email_on_failure' AIRFLOW_CTX_EXECUTION_DATE='2023-12-21T23:37:08.623264+00:00' AIRFLOW_CTX_TRY_NUMBER='3' AIRFLOW_CTX_DAG_RUN_ID='manual__2023-12-21T23:37:08.623264+00:00'
[2023-12-21T23:42:24.682+0000] {taskinstance.py:1937} ERROR - Task failed with exception
Traceback (most recent call last):
  File "/home/airflow/.local/lib/python3.8/site-packages/airflow/operators/python.py", line 192, in execute
    return_value = self.execute_callable()
  File "/home/airflow/.local/lib/python3.8/site-packages/airflow/operators/python.py", line 209, in execute_callable
    return self.python_callable(*self.op_args, **self.op_kwargs)
TypeError: enviar_email() missing 1 required positional argument: 'context'
[2023-12-21T23:42:24.709+0000] {taskinstance.py:1400} INFO - Marking task as UP_FOR_RETRY. dag_id=liverpool_dag, task_id=send_email_on_failure, execution_date=20231221T233708, start_date=20231221T234224, end_date=20231221T234224
[2023-12-21T23:42:24.739+0000] {standard_task_runner.py:104} ERROR - Failed to execute job 389 for task send_email_on_failure (enviar_email() missing 1 required positional argument: 'context'; 407)
[2023-12-21T23:42:24.753+0000] {local_task_job_runner.py:228} INFO - Task exited with return code 1
[2023-12-21T23:42:24.781+0000] {taskinstance.py:2778} INFO - 0 downstream tasks scheduled from follow-on schedule check
