[2023-12-21T23:24:20.512+0000] {taskinstance.py:1159} INFO - Dependencies all met for dep_context=non-requeueable deps ti=<TaskInstance: liverpool_dag.send_email_on_failure manual__2023-12-21T23:21:07.499052+00:00 [queued]>
[2023-12-21T23:24:20.532+0000] {taskinstance.py:1159} INFO - Dependencies all met for dep_context=requeueable deps ti=<TaskInstance: liverpool_dag.send_email_on_failure manual__2023-12-21T23:21:07.499052+00:00 [queued]>
[2023-12-21T23:24:20.533+0000] {taskinstance.py:1361} INFO - Starting attempt 1 of 4
[2023-12-21T23:24:20.559+0000] {taskinstance.py:1382} INFO - Executing <Task(PythonOperator): send_email_on_failure> on 2023-12-21 23:21:07.499052+00:00
[2023-12-21T23:24:20.567+0000] {standard_task_runner.py:57} INFO - Started process 340 to run task
[2023-12-21T23:24:20.576+0000] {standard_task_runner.py:84} INFO - Running: ['***', 'tasks', 'run', 'liverpool_dag', 'send_email_on_failure', 'manual__2023-12-21T23:21:07.499052+00:00', '--job-id', '378', '--raw', '--subdir', 'DAGS_FOLDER/liverpool.py', '--cfg-path', '/tmp/tmp_7fq69cw']
[2023-12-21T23:24:20.581+0000] {standard_task_runner.py:85} INFO - Job 378: Subtask send_email_on_failure
[2023-12-21T23:24:20.680+0000] {task_command.py:416} INFO - Running <TaskInstance: liverpool_dag.send_email_on_failure manual__2023-12-21T23:21:07.499052+00:00 [running]> on host d017a9b7b4e6
[2023-12-21T23:24:20.903+0000] {taskinstance.py:1662} INFO - Exporting env vars: AIRFLOW_CTX_DAG_OWNER='***' AIRFLOW_CTX_DAG_ID='liverpool_dag' AIRFLOW_CTX_TASK_ID='send_email_on_failure' AIRFLOW_CTX_EXECUTION_DATE='2023-12-21T23:21:07.499052+00:00' AIRFLOW_CTX_TRY_NUMBER='1' AIRFLOW_CTX_DAG_RUN_ID='manual__2023-12-21T23:21:07.499052+00:00'
[2023-12-21T23:24:20.905+0000] {taskinstance.py:1937} ERROR - Task failed with exception
Traceback (most recent call last):
  File "/home/airflow/.local/lib/python3.8/site-packages/airflow/operators/python.py", line 192, in execute
    return_value = self.execute_callable()
  File "/home/airflow/.local/lib/python3.8/site-packages/airflow/operators/python.py", line 209, in execute_callable
    return self.python_callable(*self.op_args, **self.op_kwargs)
TypeError: enviar_email() missing 1 required positional argument: 'context'
[2023-12-21T23:24:20.921+0000] {taskinstance.py:1400} INFO - Marking task as UP_FOR_RETRY. dag_id=liverpool_dag, task_id=send_email_on_failure, execution_date=20231221T232107, start_date=20231221T232420, end_date=20231221T232420
[2023-12-21T23:24:20.942+0000] {standard_task_runner.py:104} ERROR - Failed to execute job 378 for task send_email_on_failure (enviar_email() missing 1 required positional argument: 'context'; 340)
[2023-12-21T23:24:20.988+0000] {local_task_job_runner.py:228} INFO - Task exited with return code 1
[2023-12-21T23:24:21.043+0000] {taskinstance.py:2778} INFO - 0 downstream tasks scheduled from follow-on schedule check
