[2023-12-18T19:48:24.150+0000] {taskinstance.py:1159} INFO - Dependencies all met for dep_context=non-requeueable deps ti=<TaskInstance: liverpool_dag.process_data manual__2023-12-18T19:47:15.239608+00:00 [queued]>
[2023-12-18T19:48:24.162+0000] {taskinstance.py:1159} INFO - Dependencies all met for dep_context=requeueable deps ti=<TaskInstance: liverpool_dag.process_data manual__2023-12-18T19:47:15.239608+00:00 [queued]>
[2023-12-18T19:48:24.163+0000] {taskinstance.py:1361} INFO - Starting attempt 2 of 4
[2023-12-18T19:48:24.199+0000] {taskinstance.py:1382} INFO - Executing <Task(PythonOperator): process_data> on 2023-12-18 19:47:15.239608+00:00
[2023-12-18T19:48:24.205+0000] {standard_task_runner.py:57} INFO - Started process 235 to run task
[2023-12-18T19:48:24.208+0000] {standard_task_runner.py:84} INFO - Running: ['***', 'tasks', 'run', 'liverpool_dag', 'process_data', 'manual__2023-12-18T19:47:15.239608+00:00', '--job-id', '149', '--raw', '--subdir', 'DAGS_FOLDER/liverpool.py', '--cfg-path', '/tmp/tmp9o95o3ft']
[2023-12-18T19:48:24.211+0000] {standard_task_runner.py:85} INFO - Job 149: Subtask process_data
[2023-12-18T19:48:24.280+0000] {task_command.py:416} INFO - Running <TaskInstance: liverpool_dag.process_data manual__2023-12-18T19:47:15.239608+00:00 [running]> on host d017a9b7b4e6
[2023-12-18T19:48:24.396+0000] {taskinstance.py:1662} INFO - Exporting env vars: AIRFLOW_CTX_DAG_OWNER='***' AIRFLOW_CTX_DAG_ID='liverpool_dag' AIRFLOW_CTX_TASK_ID='process_data' AIRFLOW_CTX_EXECUTION_DATE='2023-12-18T19:47:15.239608+00:00' AIRFLOW_CTX_TRY_NUMBER='2' AIRFLOW_CTX_DAG_RUN_ID='manual__2023-12-18T19:47:15.239608+00:00'
[2023-12-18T19:48:24.398+0000] {taskinstance.py:1937} ERROR - Task failed with exception
Traceback (most recent call last):
  File "/home/airflow/.local/lib/python3.8/site-packages/airflow/operators/python.py", line 192, in execute
    return_value = self.execute_callable()
  File "/home/airflow/.local/lib/python3.8/site-packages/airflow/operators/python.py", line 209, in execute_callable
    return self.python_callable(*self.op_args, **self.op_kwargs)
TypeError: process_data_callable() missing 1 required positional argument: 'kwargs'
[2023-12-18T19:48:24.413+0000] {taskinstance.py:1400} INFO - Marking task as UP_FOR_RETRY. dag_id=liverpool_dag, task_id=process_data, execution_date=20231218T194715, start_date=20231218T194824, end_date=20231218T194824
[2023-12-18T19:48:24.428+0000] {standard_task_runner.py:104} ERROR - Failed to execute job 149 for task process_data (process_data_callable() missing 1 required positional argument: 'kwargs'; 235)
[2023-12-18T19:48:24.462+0000] {local_task_job_runner.py:228} INFO - Task exited with return code 1
[2023-12-18T19:48:24.541+0000] {taskinstance.py:2778} INFO - 0 downstream tasks scheduled from follow-on schedule check
