[2023-12-21T23:40:18.131+0000] {taskinstance.py:1159} INFO - Dependencies all met for dep_context=non-requeueable deps ti=<TaskInstance: liverpool_dag.connect_to_db manual__2023-12-21T23:37:08.623264+00:00 [queued]>
[2023-12-21T23:40:18.150+0000] {taskinstance.py:1159} INFO - Dependencies all met for dep_context=requeueable deps ti=<TaskInstance: liverpool_dag.connect_to_db manual__2023-12-21T23:37:08.623264+00:00 [queued]>
[2023-12-21T23:40:18.151+0000] {taskinstance.py:1361} INFO - Starting attempt 4 of 4
[2023-12-21T23:40:18.177+0000] {taskinstance.py:1382} INFO - Executing <Task(PythonOperator): connect_to_db> on 2023-12-21 23:37:08.623264+00:00
[2023-12-21T23:40:18.183+0000] {standard_task_runner.py:57} INFO - Started process 326 to run task
[2023-12-21T23:40:18.187+0000] {standard_task_runner.py:84} INFO - Running: ['***', 'tasks', 'run', 'liverpool_dag', 'connect_to_db', 'manual__2023-12-21T23:37:08.623264+00:00', '--job-id', '386', '--raw', '--subdir', 'DAGS_FOLDER/liverpool.py', '--cfg-path', '/tmp/tmpw4047f61']
[2023-12-21T23:40:18.191+0000] {standard_task_runner.py:85} INFO - Job 386: Subtask connect_to_db
[2023-12-21T23:40:18.272+0000] {task_command.py:416} INFO - Running <TaskInstance: liverpool_dag.connect_to_db manual__2023-12-21T23:37:08.623264+00:00 [running]> on host d017a9b7b4e6
[2023-12-21T23:40:18.412+0000] {taskinstance.py:1662} INFO - Exporting env vars: AIRFLOW_CTX_DAG_OWNER='***' AIRFLOW_CTX_DAG_ID='liverpool_dag' AIRFLOW_CTX_TASK_ID='connect_to_db' AIRFLOW_CTX_EXECUTION_DATE='2023-12-21T23:37:08.623264+00:00' AIRFLOW_CTX_TRY_NUMBER='4' AIRFLOW_CTX_DAG_RUN_ID='manual__2023-12-21T23:37:08.623264+00:00'
[2023-12-21T23:40:18.436+0000] {utils.py:23} ERROR - Error al conectarse a la base de datos: Can't load plugin: sqlalchemy.dialects:***
[2023-12-21T23:40:18.437+0000] {taskinstance.py:1937} ERROR - Task failed with exception
Traceback (most recent call last):
  File "/home/airflow/.local/lib/python3.8/site-packages/airflow/operators/python.py", line 192, in execute
    return_value = self.execute_callable()
  File "/home/airflow/.local/lib/python3.8/site-packages/airflow/operators/python.py", line 209, in execute_callable
    return self.python_callable(*self.op_args, **self.op_kwargs)
  File "/opt/airflow/scripts/utils.py", line 18, in build_conn_from_airflow_conn_id
    engine = create_engine(f'airflow://{conn_id}')
  File "<string>", line 2, in create_engine
  File "/home/airflow/.local/lib/python3.8/site-packages/sqlalchemy/util/deprecations.py", line 375, in warned
    return fn(*args, **kwargs)
  File "/home/airflow/.local/lib/python3.8/site-packages/sqlalchemy/engine/create.py", line 518, in create_engine
    entrypoint = u._get_entrypoint()
  File "/home/airflow/.local/lib/python3.8/site-packages/sqlalchemy/engine/url.py", line 662, in _get_entrypoint
    cls = registry.load(name)
  File "/home/airflow/.local/lib/python3.8/site-packages/sqlalchemy/util/langhelpers.py", line 343, in load
    raise exc.NoSuchModuleError(
sqlalchemy.exc.NoSuchModuleError: Can't load plugin: sqlalchemy.dialects:***
[2023-12-21T23:40:18.461+0000] {taskinstance.py:1400} INFO - Marking task as FAILED. dag_id=liverpool_dag, task_id=connect_to_db, execution_date=20231221T233708, start_date=20231221T234018, end_date=20231221T234018
[2023-12-21T23:40:18.479+0000] {standard_task_runner.py:104} ERROR - Failed to execute job 386 for task connect_to_db (Can't load plugin: sqlalchemy.dialects:***; 326)
[2023-12-21T23:40:18.521+0000] {local_task_job_runner.py:228} INFO - Task exited with return code 1
[2023-12-21T23:40:18.582+0000] {taskinstance.py:2778} INFO - 1 downstream tasks scheduled from follow-on schedule check
