[2023-12-22T00:02:31.830+0000] {taskinstance.py:1159} INFO - Dependencies all met for dep_context=non-requeueable deps ti=<TaskInstance: liverpool_dag.connect_to_db manual__2023-12-22T00:00:21.950983+00:00 [queued]>
[2023-12-22T00:02:31.874+0000] {taskinstance.py:1159} INFO - Dependencies all met for dep_context=requeueable deps ti=<TaskInstance: liverpool_dag.connect_to_db manual__2023-12-22T00:00:21.950983+00:00 [queued]>
[2023-12-22T00:02:31.877+0000] {taskinstance.py:1361} INFO - Starting attempt 3 of 4
[2023-12-22T00:02:31.954+0000] {taskinstance.py:1382} INFO - Executing <Task(PythonOperator): connect_to_db> on 2023-12-22 00:00:21.950983+00:00
[2023-12-22T00:02:31.971+0000] {standard_task_runner.py:57} INFO - Started process 289 to run task
[2023-12-22T00:02:31.987+0000] {standard_task_runner.py:84} INFO - Running: ['***', 'tasks', 'run', 'liverpool_dag', 'connect_to_db', 'manual__2023-12-22T00:00:21.950983+00:00', '--job-id', '404', '--raw', '--subdir', 'DAGS_FOLDER/liverpool.py', '--cfg-path', '/tmp/tmp3w68em1s']
[2023-12-22T00:02:32.033+0000] {standard_task_runner.py:85} INFO - Job 404: Subtask connect_to_db
[2023-12-22T00:02:32.316+0000] {task_command.py:416} INFO - Running <TaskInstance: liverpool_dag.connect_to_db manual__2023-12-22T00:00:21.950983+00:00 [running]> on host d017a9b7b4e6
[2023-12-22T00:02:32.501+0000] {taskinstance.py:1662} INFO - Exporting env vars: AIRFLOW_CTX_DAG_OWNER='***' AIRFLOW_CTX_DAG_ID='liverpool_dag' AIRFLOW_CTX_TASK_ID='connect_to_db' AIRFLOW_CTX_EXECUTION_DATE='2023-12-22T00:00:21.950983+00:00' AIRFLOW_CTX_TRY_NUMBER='3' AIRFLOW_CTX_DAG_RUN_ID='manual__2023-12-22T00:00:21.950983+00:00'
[2023-12-22T00:02:32.595+0000] {utils.py:24} ERROR - Error al conectarse a la base de datos URL: ***://coder_redshit: Can't load plugin: sqlalchemy.dialects:***
[2023-12-22T00:02:32.599+0000] {taskinstance.py:1937} ERROR - Task failed with exception
Traceback (most recent call last):
  File "/home/airflow/.local/lib/python3.8/site-packages/airflow/operators/python.py", line 192, in execute
    return_value = self.execute_callable()
  File "/home/airflow/.local/lib/python3.8/site-packages/airflow/operators/python.py", line 209, in execute_callable
    return self.python_callable(*self.op_args, **self.op_kwargs)
  File "/opt/airflow/scripts/utils.py", line 19, in build_conn_from_airflow_conn_id
    engine = create_engine(engine_url)
  File "<string>", line 2, in create_engine
  File "/home/airflow/.local/lib/python3.8/site-packages/sqlalchemy/util/deprecations.py", line 375, in warned
    return fn(*args, **kwargs)
  File "/home/airflow/.local/lib/python3.8/site-packages/sqlalchemy/engine/create.py", line 518, in create_engine
    entrypoint = u._get_entrypoint()
  File "/home/airflow/.local/lib/python3.8/site-packages/sqlalchemy/engine/url.py", line 662, in _get_entrypoint
    cls = registry.load(name)
  File "/home/airflow/.local/lib/python3.8/site-packages/sqlalchemy/util/langhelpers.py", line 343, in load
    raise exc.NoSuchModuleError(
sqlalchemy.exc.NoSuchModuleError: Can't load plugin: sqlalchemy.dialects:***
[2023-12-22T00:02:32.649+0000] {taskinstance.py:1400} INFO - Marking task as UP_FOR_RETRY. dag_id=liverpool_dag, task_id=connect_to_db, execution_date=20231222T000021, start_date=20231222T000231, end_date=20231222T000232
[2023-12-22T00:02:32.683+0000] {standard_task_runner.py:104} ERROR - Failed to execute job 404 for task connect_to_db (Can't load plugin: sqlalchemy.dialects:***; 289)
[2023-12-22T00:02:32.725+0000] {local_task_job_runner.py:228} INFO - Task exited with return code 1
[2023-12-22T00:02:32.810+0000] {taskinstance.py:2778} INFO - 0 downstream tasks scheduled from follow-on schedule check
