[2023-12-19T16:18:52.806+0000] {taskinstance.py:1159} INFO - Dependencies all met for dep_context=non-requeueable deps ti=<TaskInstance: liverpool_dag.load_data manual__2023-12-19T16:15:29.405839+00:00 [queued]>
[2023-12-19T16:18:52.817+0000] {taskinstance.py:1159} INFO - Dependencies all met for dep_context=requeueable deps ti=<TaskInstance: liverpool_dag.load_data manual__2023-12-19T16:15:29.405839+00:00 [queued]>
[2023-12-19T16:18:52.818+0000] {taskinstance.py:1361} INFO - Starting attempt 4 of 4
[2023-12-19T16:18:52.843+0000] {taskinstance.py:1382} INFO - Executing <Task(PythonOperator): load_data> on 2023-12-19 16:15:29.405839+00:00
[2023-12-19T16:18:52.854+0000] {standard_task_runner.py:57} INFO - Started process 316 to run task
[2023-12-19T16:18:52.860+0000] {standard_task_runner.py:84} INFO - Running: ['***', 'tasks', 'run', 'liverpool_dag', 'load_data', 'manual__2023-12-19T16:15:29.405839+00:00', '--job-id', '243', '--raw', '--subdir', 'DAGS_FOLDER/liverpool.py', '--cfg-path', '/tmp/tmpum3l16ms']
[2023-12-19T16:18:52.863+0000] {standard_task_runner.py:85} INFO - Job 243: Subtask load_data
[2023-12-19T16:18:52.964+0000] {task_command.py:416} INFO - Running <TaskInstance: liverpool_dag.load_data manual__2023-12-19T16:15:29.405839+00:00 [running]> on host d017a9b7b4e6
[2023-12-19T16:18:53.131+0000] {taskinstance.py:1662} INFO - Exporting env vars: AIRFLOW_CTX_DAG_OWNER='***' AIRFLOW_CTX_DAG_ID='liverpool_dag' AIRFLOW_CTX_TASK_ID='load_data' AIRFLOW_CTX_EXECUTION_DATE='2023-12-19T16:15:29.405839+00:00' AIRFLOW_CTX_TRY_NUMBER='4' AIRFLOW_CTX_DAG_RUN_ID='manual__2023-12-19T16:15:29.405839+00:00'
[2023-12-19T16:18:53.179+0000] {utils.py:22} ERROR - Error al conectarse a la base de datos: Can't load plugin: sqlalchemy.dialects:***
[2023-12-19T16:18:53.180+0000] {taskinstance.py:1937} ERROR - Task failed with exception
Traceback (most recent call last):
  File "/home/airflow/.local/lib/python3.8/site-packages/airflow/operators/python.py", line 192, in execute
    return_value = self.execute_callable()
  File "/home/airflow/.local/lib/python3.8/site-packages/airflow/operators/python.py", line 209, in execute_callable
    return self.python_callable(*self.op_args, **self.op_kwargs)
  File "/opt/airflow/dags/liverpool.py", line 36, in load_data_callable
    logging.error("No se pudo obtener el motor de la base de datos.")
NameError: name 'logging' is not defined
[2023-12-19T16:18:53.201+0000] {taskinstance.py:1400} INFO - Marking task as FAILED. dag_id=liverpool_dag, task_id=load_data, execution_date=20231219T161529, start_date=20231219T161852, end_date=20231219T161853
[2023-12-19T16:18:53.221+0000] {standard_task_runner.py:104} ERROR - Failed to execute job 243 for task load_data (name 'logging' is not defined; 316)
[2023-12-19T16:18:53.234+0000] {local_task_job_runner.py:228} INFO - Task exited with return code 1
[2023-12-19T16:18:53.277+0000] {taskinstance.py:2778} INFO - 0 downstream tasks scheduled from follow-on schedule check
