[2023-12-21T14:15:02.816+0000] {taskinstance.py:1159} INFO - Dependencies all met for dep_context=non-requeueable deps ti=<TaskInstance: liverpool_dag.obtain_data_from_api manual__2023-12-21T14:14:52.018448+00:00 [queued]>
[2023-12-21T14:15:02.830+0000] {taskinstance.py:1159} INFO - Dependencies all met for dep_context=requeueable deps ti=<TaskInstance: liverpool_dag.obtain_data_from_api manual__2023-12-21T14:14:52.018448+00:00 [queued]>
[2023-12-21T14:15:02.831+0000] {taskinstance.py:1361} INFO - Starting attempt 1 of 4
[2023-12-21T14:15:02.852+0000] {taskinstance.py:1382} INFO - Executing <Task(PythonOperator): obtain_data_from_api> on 2023-12-21 14:14:52.018448+00:00
[2023-12-21T14:15:02.891+0000] {standard_task_runner.py:57} INFO - Started process 260 to run task
[2023-12-21T14:15:02.899+0000] {standard_task_runner.py:84} INFO - Running: ['***', 'tasks', 'run', 'liverpool_dag', 'obtain_data_from_api', 'manual__2023-12-21T14:14:52.018448+00:00', '--job-id', '261', '--raw', '--subdir', 'DAGS_FOLDER/liverpool.py', '--cfg-path', '/tmp/tmpkzqh3_1o']
[2023-12-21T14:15:02.906+0000] {standard_task_runner.py:85} INFO - Job 261: Subtask obtain_data_from_api
[2023-12-21T14:15:03.050+0000] {task_command.py:416} INFO - Running <TaskInstance: liverpool_dag.obtain_data_from_api manual__2023-12-21T14:14:52.018448+00:00 [running]> on host d017a9b7b4e6
[2023-12-21T14:15:03.221+0000] {taskinstance.py:1662} INFO - Exporting env vars: AIRFLOW_CTX_DAG_OWNER='***' AIRFLOW_CTX_DAG_ID='liverpool_dag' AIRFLOW_CTX_TASK_ID='obtain_data_from_api' AIRFLOW_CTX_EXECUTION_DATE='2023-12-21T14:14:52.018448+00:00' AIRFLOW_CTX_TRY_NUMBER='1' AIRFLOW_CTX_DAG_RUN_ID='manual__2023-12-21T14:14:52.018448+00:00'
[2023-12-21T14:15:11.040+0000] {taskinstance.py:1937} ERROR - Task failed with exception
Traceback (most recent call last):
  File "/home/airflow/.local/lib/python3.8/site-packages/urllib3/connection.py", line 174, in _new_conn
    conn = connection.create_connection(
  File "/home/airflow/.local/lib/python3.8/site-packages/urllib3/util/connection.py", line 72, in create_connection
    for res in socket.getaddrinfo(host, port, family, socket.SOCK_STREAM):
  File "/usr/local/lib/python3.8/socket.py", line 918, in getaddrinfo
    for res in _socket.getaddrinfo(host, port, family, type, proto, flags):
socket.gaierror: [Errno -3] Temporary failure in name resolution

During handling of the above exception, another exception occurred:

Traceback (most recent call last):
  File "/home/airflow/.local/lib/python3.8/site-packages/urllib3/connectionpool.py", line 715, in urlopen
    httplib_response = self._make_request(
  File "/home/airflow/.local/lib/python3.8/site-packages/urllib3/connectionpool.py", line 404, in _make_request
    self._validate_conn(conn)
  File "/home/airflow/.local/lib/python3.8/site-packages/urllib3/connectionpool.py", line 1058, in _validate_conn
    conn.connect()
  File "/home/airflow/.local/lib/python3.8/site-packages/urllib3/connection.py", line 363, in connect
    self.sock = conn = self._new_conn()
  File "/home/airflow/.local/lib/python3.8/site-packages/urllib3/connection.py", line 186, in _new_conn
    raise NewConnectionError(
urllib3.exceptions.NewConnectionError: <urllib3.connection.HTTPSConnection object at 0x7fc1d1f4aa90>: Failed to establish a new connection: [Errno -3] Temporary failure in name resolution

During handling of the above exception, another exception occurred:

Traceback (most recent call last):
  File "/home/airflow/.local/lib/python3.8/site-packages/requests/adapters.py", line 486, in send
    resp = conn.urlopen(
  File "/home/airflow/.local/lib/python3.8/site-packages/urllib3/connectionpool.py", line 799, in urlopen
    retries = retries.increment(
  File "/home/airflow/.local/lib/python3.8/site-packages/urllib3/util/retry.py", line 592, in increment
    raise MaxRetryError(_pool, url, error or ResponseError(cause))
urllib3.exceptions.MaxRetryError: HTTPSConnectionPool(host='www.thesportsdb.com', port=443): Max retries exceeded with url: //api/v1/json/3/eventslast.php?id=133602 (Caused by NewConnectionError('<urllib3.connection.HTTPSConnection object at 0x7fc1d1f4aa90>: Failed to establish a new connection: [Errno -3] Temporary failure in name resolution'))

During handling of the above exception, another exception occurred:

Traceback (most recent call last):
  File "/home/airflow/.local/lib/python3.8/site-packages/airflow/operators/python.py", line 192, in execute
    return_value = self.execute_callable()
  File "/home/airflow/.local/lib/python3.8/site-packages/airflow/operators/python.py", line 209, in execute_callable
    return self.python_callable(*self.op_args, **self.op_kwargs)
  File "/opt/airflow/scripts/main.py", line 21, in obtener_datos_desde_api
    resp = requests.get(url)
  File "/home/airflow/.local/lib/python3.8/site-packages/requests/api.py", line 73, in get
    return request("get", url, params=params, **kwargs)
  File "/home/airflow/.local/lib/python3.8/site-packages/requests/api.py", line 59, in request
    return session.request(method=method, url=url, **kwargs)
  File "/home/airflow/.local/lib/python3.8/site-packages/requests/sessions.py", line 589, in request
    resp = self.send(prep, **send_kwargs)
  File "/home/airflow/.local/lib/python3.8/site-packages/requests/sessions.py", line 703, in send
    r = adapter.send(request, **kwargs)
  File "/home/airflow/.local/lib/python3.8/site-packages/requests/adapters.py", line 519, in send
    raise ConnectionError(e, request=request)
requests.exceptions.ConnectionError: HTTPSConnectionPool(host='www.thesportsdb.com', port=443): Max retries exceeded with url: //api/v1/json/3/eventslast.php?id=133602 (Caused by NewConnectionError('<urllib3.connection.HTTPSConnection object at 0x7fc1d1f4aa90>: Failed to establish a new connection: [Errno -3] Temporary failure in name resolution'))
[2023-12-21T14:15:17.558+0000] {taskinstance.py:1400} INFO - Marking task as UP_FOR_RETRY. dag_id=liverpool_dag, task_id=obtain_data_from_api, execution_date=20231221T141452, start_date=20231221T141502, end_date=20231221T141517
[2023-12-21T14:15:18.164+0000] {standard_task_runner.py:104} ERROR - Failed to execute job 261 for task obtain_data_from_api (HTTPSConnectionPool(host='www.thesportsdb.com', port=443): Max retries exceeded with url: //api/v1/json/3/eventslast.php?id=133602 (Caused by NewConnectionError('<urllib3.connection.HTTPSConnection object at 0x7fc1d1f4aa90>: Failed to establish a new connection: [Errno -3] Temporary failure in name resolution')); 260)
[2023-12-21T14:15:18.386+0000] {local_task_job_runner.py:228} INFO - Task exited with return code 1
[2023-12-21T14:15:18.428+0000] {taskinstance.py:2778} INFO - 0 downstream tasks scheduled from follow-on schedule check
