[2023-12-15T17:47:24.015+0000] {taskinstance.py:1159} INFO - Dependencies all met for dep_context=non-requeueable deps ti=<TaskInstance: liverpool_dag.connect_to_db manual__2023-12-15T17:47:21.170111+00:00 [queued]>
[2023-12-15T17:47:24.027+0000] {taskinstance.py:1159} INFO - Dependencies all met for dep_context=requeueable deps ti=<TaskInstance: liverpool_dag.connect_to_db manual__2023-12-15T17:47:21.170111+00:00 [queued]>
[2023-12-15T17:47:24.028+0000] {taskinstance.py:1361} INFO - Starting attempt 1 of 4
[2023-12-15T17:47:24.049+0000] {taskinstance.py:1382} INFO - Executing <Task(PythonOperator): connect_to_db> on 2023-12-15 17:47:21.170111+00:00
[2023-12-15T17:47:24.069+0000] {standard_task_runner.py:57} INFO - Started process 230 to run task
[2023-12-15T17:47:24.077+0000] {standard_task_runner.py:84} INFO - Running: ['***', 'tasks', 'run', 'liverpool_dag', 'connect_to_db', 'manual__2023-12-15T17:47:21.170111+00:00', '--job-id', '16', '--raw', '--subdir', 'DAGS_FOLDER/liverpool.py', '--cfg-path', '/tmp/tmpdqguhkgm']
[2023-12-15T17:47:24.086+0000] {standard_task_runner.py:85} INFO - Job 16: Subtask connect_to_db
[2023-12-15T17:47:24.193+0000] {task_command.py:416} INFO - Running <TaskInstance: liverpool_dag.connect_to_db manual__2023-12-15T17:47:21.170111+00:00 [running]> on host 9c6625b9960e
[2023-12-15T17:47:24.330+0000] {taskinstance.py:1662} INFO - Exporting env vars: AIRFLOW_CTX_DAG_OWNER='***' AIRFLOW_CTX_DAG_ID='liverpool_dag' AIRFLOW_CTX_TASK_ID='connect_to_db' AIRFLOW_CTX_EXECUTION_DATE='2023-12-15T17:47:21.170111+00:00' AIRFLOW_CTX_TRY_NUMBER='1' AIRFLOW_CTX_DAG_RUN_ID='manual__2023-12-15T17:47:21.170111+00:00'
[2023-12-15T17:47:24.333+0000] {taskinstance.py:1937} ERROR - Task failed with exception
Traceback (most recent call last):
  File "/home/airflow/.local/lib/python3.8/site-packages/airflow/operators/python.py", line 192, in execute
    return_value = self.execute_callable()
  File "/home/airflow/.local/lib/python3.8/site-packages/airflow/operators/python.py", line 209, in execute_callable
    return self.python_callable(*self.op_args, **self.op_kwargs)
  File "/opt/airflow/scripts/utils.py", line 52, in connect_to_db
    engine = sa.create_engine(conn_string)
  File "<string>", line 2, in create_engine
  File "/home/airflow/.local/lib/python3.8/site-packages/sqlalchemy/util/deprecations.py", line 375, in warned
    return fn(*args, **kwargs)
  File "/home/airflow/.local/lib/python3.8/site-packages/sqlalchemy/engine/create.py", line 516, in create_engine
    u, plugins, kwargs = u._instantiate_plugins(kwargs)
AttributeError: 'NoneType' object has no attribute '_instantiate_plugins'
[2023-12-15T17:47:24.357+0000] {taskinstance.py:1400} INFO - Marking task as UP_FOR_RETRY. dag_id=liverpool_dag, task_id=connect_to_db, execution_date=20231215T174721, start_date=20231215T174724, end_date=20231215T174724
[2023-12-15T17:47:24.377+0000] {standard_task_runner.py:104} ERROR - Failed to execute job 16 for task connect_to_db ('NoneType' object has no attribute '_instantiate_plugins'; 230)
[2023-12-15T17:47:24.416+0000] {local_task_job_runner.py:228} INFO - Task exited with return code 1
[2023-12-15T17:47:24.446+0000] {taskinstance.py:2778} INFO - 0 downstream tasks scheduled from follow-on schedule check
