[2023-12-15T18:01:02.636+0000] {taskinstance.py:1159} INFO - Dependencies all met for dep_context=non-requeueable deps ti=<TaskInstance: liverpool_dag.connect_to_db manual__2023-12-15T17:57:52.687439+00:00 [queued]>
[2023-12-15T18:01:02.659+0000] {taskinstance.py:1159} INFO - Dependencies all met for dep_context=requeueable deps ti=<TaskInstance: liverpool_dag.connect_to_db manual__2023-12-15T17:57:52.687439+00:00 [queued]>
[2023-12-15T18:01:02.661+0000] {taskinstance.py:1361} INFO - Starting attempt 4 of 4
[2023-12-15T18:01:02.698+0000] {taskinstance.py:1382} INFO - Executing <Task(PythonOperator): connect_to_db> on 2023-12-15 17:57:52.687439+00:00
[2023-12-15T18:01:02.708+0000] {standard_task_runner.py:57} INFO - Started process 355 to run task
[2023-12-15T18:01:02.714+0000] {standard_task_runner.py:84} INFO - Running: ['***', 'tasks', 'run', 'liverpool_dag', 'connect_to_db', 'manual__2023-12-15T17:57:52.687439+00:00', '--job-id', '24', '--raw', '--subdir', 'DAGS_FOLDER/liverpool.py', '--cfg-path', '/tmp/tmpuc5ytz61']
[2023-12-15T18:01:02.719+0000] {standard_task_runner.py:85} INFO - Job 24: Subtask connect_to_db
[2023-12-15T18:01:02.800+0000] {task_command.py:416} INFO - Running <TaskInstance: liverpool_dag.connect_to_db manual__2023-12-15T17:57:52.687439+00:00 [running]> on host 9c6625b9960e
[2023-12-15T18:01:02.913+0000] {taskinstance.py:1662} INFO - Exporting env vars: AIRFLOW_CTX_DAG_OWNER='***' AIRFLOW_CTX_DAG_ID='liverpool_dag' AIRFLOW_CTX_TASK_ID='connect_to_db' AIRFLOW_CTX_EXECUTION_DATE='2023-12-15T17:57:52.687439+00:00' AIRFLOW_CTX_TRY_NUMBER='4' AIRFLOW_CTX_DAG_RUN_ID='manual__2023-12-15T17:57:52.687439+00:00'
[2023-12-15T18:01:02.915+0000] {taskinstance.py:1937} ERROR - Task failed with exception
Traceback (most recent call last):
  File "/home/airflow/.local/lib/python3.8/site-packages/airflow/operators/python.py", line 192, in execute
    return_value = self.execute_callable()
  File "/home/airflow/.local/lib/python3.8/site-packages/airflow/operators/python.py", line 209, in execute_callable
    return self.python_callable(*self.op_args, **self.op_kwargs)
  File "/opt/airflow/scripts/utils.py", line 53, in connect_to_db
    engine = sa.create_engine(conn_string)
  File "<string>", line 2, in create_engine
  File "/home/airflow/.local/lib/python3.8/site-packages/sqlalchemy/util/deprecations.py", line 375, in warned
    return fn(*args, **kwargs)
  File "/home/airflow/.local/lib/python3.8/site-packages/sqlalchemy/engine/create.py", line 516, in create_engine
    u, plugins, kwargs = u._instantiate_plugins(kwargs)
AttributeError: 'NoneType' object has no attribute '_instantiate_plugins'
[2023-12-15T18:01:02.938+0000] {taskinstance.py:1400} INFO - Marking task as FAILED. dag_id=liverpool_dag, task_id=connect_to_db, execution_date=20231215T175752, start_date=20231215T180102, end_date=20231215T180102
[2023-12-15T18:01:02.954+0000] {standard_task_runner.py:104} ERROR - Failed to execute job 24 for task connect_to_db ('NoneType' object has no attribute '_instantiate_plugins'; 355)
[2023-12-15T18:01:02.968+0000] {local_task_job_runner.py:228} INFO - Task exited with return code 1
[2023-12-15T18:01:03.037+0000] {taskinstance.py:2778} INFO - 0 downstream tasks scheduled from follow-on schedule check
