[2023-12-22T02:56:33.303+0000] {taskinstance.py:1159} INFO - Dependencies all met for dep_context=non-requeueable deps ti=<TaskInstance: liverpool_dag.connect_to_db manual__2023-12-22T02:53:23.761005+00:00 [queued]>
[2023-12-22T02:56:33.323+0000] {taskinstance.py:1159} INFO - Dependencies all met for dep_context=requeueable deps ti=<TaskInstance: liverpool_dag.connect_to_db manual__2023-12-22T02:53:23.761005+00:00 [queued]>
[2023-12-22T02:56:33.325+0000] {taskinstance.py:1361} INFO - Starting attempt 4 of 4
[2023-12-22T02:56:33.405+0000] {taskinstance.py:1382} INFO - Executing <Task(PythonOperator): connect_to_db> on 2023-12-22 02:53:23.761005+00:00
[2023-12-22T02:56:33.421+0000] {standard_task_runner.py:57} INFO - Started process 307 to run task
[2023-12-22T02:56:33.435+0000] {standard_task_runner.py:84} INFO - Running: ['***', 'tasks', 'run', 'liverpool_dag', 'connect_to_db', 'manual__2023-12-22T02:53:23.761005+00:00', '--job-id', '451', '--raw', '--subdir', 'DAGS_FOLDER/liverpool.py', '--cfg-path', '/tmp/tmp6le36evj']
[2023-12-22T02:56:33.448+0000] {standard_task_runner.py:85} INFO - Job 451: Subtask connect_to_db
[2023-12-22T02:56:33.708+0000] {task_command.py:416} INFO - Running <TaskInstance: liverpool_dag.connect_to_db manual__2023-12-22T02:53:23.761005+00:00 [running]> on host d017a9b7b4e6
[2023-12-22T02:56:33.892+0000] {taskinstance.py:1662} INFO - Exporting env vars: AIRFLOW_CTX_DAG_OWNER='***' AIRFLOW_CTX_DAG_ID='liverpool_dag' AIRFLOW_CTX_TASK_ID='connect_to_db' AIRFLOW_CTX_EXECUTION_DATE='2023-12-22T02:53:23.761005+00:00' AIRFLOW_CTX_TRY_NUMBER='4' AIRFLOW_CTX_DAG_RUN_ID='manual__2023-12-22T02:53:23.761005+00:00'
[2023-12-22T02:56:33.894+0000] {taskinstance.py:1937} ERROR - Task failed with exception
Traceback (most recent call last):
  File "/home/airflow/.local/lib/python3.8/site-packages/airflow/operators/python.py", line 192, in execute
    return_value = self.execute_callable()
  File "/home/airflow/.local/lib/python3.8/site-packages/airflow/operators/python.py", line 209, in execute_callable
    return self.python_callable(*self.op_args, **self.op_kwargs)
  File "/opt/airflow/scripts/utils.py", line 30, in build_conn_from_airflow_conn_id
    config = configparser.ConfigParser()
NameError: name 'configparser' is not defined
[2023-12-22T02:56:33.936+0000] {taskinstance.py:1400} INFO - Marking task as FAILED. dag_id=liverpool_dag, task_id=connect_to_db, execution_date=20231222T025323, start_date=20231222T025633, end_date=20231222T025633
[2023-12-22T02:56:33.969+0000] {standard_task_runner.py:104} ERROR - Failed to execute job 451 for task connect_to_db (name 'configparser' is not defined; 307)
[2023-12-22T02:56:34.011+0000] {local_task_job_runner.py:228} INFO - Task exited with return code 1
[2023-12-22T02:56:34.132+0000] {taskinstance.py:2778} INFO - 1 downstream tasks scheduled from follow-on schedule check
